Workbook

Sheet DCF
A1: Diploma PLC (LSE: DPLM) — DCF Valuation
A2: Bloombruh — GBP millions unless noted; share price in pence (p) | Compiled Aug 2026, real sourced inputs (see Sources tab)
A4: Key Assumptions & WACC
A5: Current Share Price (p, as quoted) | B5: 7525 | C5: 7,525p as of 22 Jul 2026 (stockanalysis.com / site pitch)
A6: Price Conversion Factor | B6: 100 | C6: Quoted price ÷ this factor = price in the model's working currency (matches the currency revenue/net debt are modeled in below). 1.0 where quoted price and model currency already match.
A7: Current Share Price (model currency) | B7: =B5/B6 | C7: =Quoted price ÷ conversion factor — this is the figure the market-cap and equity-bridge math below actually uses, so units stay consistent with revenue/net debt
A8: Shares Outstanding (m) | B8: 134.09 | C8: 134.09m (stockanalysis.com, Aug 2026)
A9: Net Debt (Net Cash if negative) | B9: 383.2 | C9: Net debt £383.2m (cash £81.7m, debt £464.9m) — stockanalysis.com
A10: Beta | B10: 1.04 | C10: 1.04 (stockanalysis.com)
A11: Risk-Free Rate | B11: 0.0499 | C11: UK 10-year gilt yield, 4.99% (4 Aug 2026, tradingeconomics.com)
A12: Equity Risk Premium | B12: 0.05 | C12: Standard mature-market equity risk premium assumption (~5%, Damodaran-style)
A13: Cost of Equity (CAPM) | B13: =B11+B10*B12 | C13: =Risk-free rate + Beta x Equity Risk Premium
A14: Pre-Tax Cost of Debt | B14: 0.058 | C14: Modeled: UK gilt yield + ~80bp investment-grade spread (assumption, not quoted)
A15: Tax Rate | B15: 0.25 | C15: UK statutory corporate tax rate, 25%
A16: After-Tax Cost of Debt | B16: =B14*(1-B15)
A17: Market Capitalization | B17: =B7*B8 | C17: =Current Share Price (model currency) x Shares Outstanding — uses the model-currency price so units match revenue/net debt below
A18: Debt (for WACC weighting) | B18: =MAX(B9,0) | C18: Simplification: uses net debt (0 if net cash) rather than gross debt, since several names here carry net-cash positions where gross debt is not a meaningful weight
A19: Total Capital (E + D) | B19: =B17+B18
A20: Weight of Equity | B20: =B17/B19
A21: Weight of Debt | B21: =B18/B19
A22: WACC | B22: =B20*B13+B21*B16
A24: Revenue & Free Cash Flow Build
A25: Fiscal Year | B25: FY0 (Actual) | C25: FY+1 | D25: FY+2 | E25: FY+3 | F25: FY+4 | G25: FY+5
A26: Revenue Growth % | B26: — | C26: 0.17 | D26: 0.14 | E26: 0.11 | F26: 0.09 | G26: 0.07
A27: Y1 from Q1 FY26 reported growth (+17%); tapering toward a mid-single-digit long-run rate as the Peerless/PAR bolt-ons annualize
A28: Revenue | B28: 1524.5 | C28: =B28*(1+C26) | D28: =C28*(1+D26) | E28: =D28*(1+E26) | F28: =E28*(1+F26) | G28: =F28*(1+G26)
A29: FY2025 revenue £1,524.5m (Diploma FY25 results, 18 Nov 2025)
A30: Operating Margin % | B30: 0.225 | C30: 0.235 | D30: 0.24 | E30: 0.24 | F30: 0.245 | G30: 0.245
A31: Modeled expanding toward FY26 guidance (>30% operating PROFIT growth, i.e. margin expansion, not just revenue growth) | FY2025 operating margin 22.5% (£342.7m op. profit / £1,524.5m revenue)
A32: EBIT | B32: =B28*B30 | C32: =C28*C30 | D32: =D28*D30 | E32: =E28*E30 | F32: =F28*F30 | G32: =G28*G30
A33: Less: Tax on EBIT | B33: =-B32*$B$15 | C33: =-C32*$B$15 | D33: =-D32*$B$15 | E33: =-E32*$B$15 | F33: =-F32*$B$15 | G33: =-G32*$B$15
A34: NOPAT | B34: =B32+B33 | C34: =C32+C33 | D34: =D32+D33 | E34: =E32+E33 | F34: =F32+F33 | G34: =G32+G33
A35: D&A (% of revenue) | B35: 0.02 | C35: 0.02 | D35: 0.02 | E35: 0.02 | F35: 0.02 | G35: 0.02
A36: Plus: D&A | B36: =B28*B35 | C36: =C28*C35 | D36: =D28*D35 | E36: =E28*E35 | F36: =F28*F35 | G36: =G28*G35
A37: Capex (% of revenue) | B37: 0.025 | C37: 0.025 | D37: 0.025 | E37: 0.025 | F37: 0.025 | G37: 0.025
A38: Less: Capex | B38: =-B28*B37 | C38: =-C28*C37 | D38: =-D28*D37 | E38: =-E28*E37 | F38: =-F28*F37 | G38: =-G28*G37
A39: Incremental NWC (% of revenue growth) | B39: 0 | C39: 0.005 | D39: 0.005 | E39: 0.005 | F39: 0.005 | G39: 0.005
A40: Less: Increase in NWC | B40: =0 | C40: =-(C28-B28)*C39 | D40: =-(D28-C28)*D39 | E40: =-(E28-D28)*E39 | F40: =-(F28-E28)*F39 | G40: =-(G28-F28)*G39
A41: Unlevered Free Cash Flow | B41: =B34+B36+B38+B40 | C41: =C34+C36+C38+C40 | D41: =D34+D36+D38+D40 | E41: =E34+E36+E38+E40 | F41: =F34+F36+F38+F40 | G41: =G34+G36+G38+G40
A43: Discounting & Valuation
...

Sheet Scenarios
A1: Diploma PLC — Bear / Base / Bull Scenario Valuation
A2: Each scenario re-runs the same 5-year FCF build with scaled growth/margin and a shifted WACC & terminal growth — not a single lever, a full re-derivation. Bear/Bull multipliers are explicit, labeled assumptions (see row below), not fabricated target prices.
B4: Bear | C4: Base | D4: Bull
A5: Growth multiplier vs. base case | B5: 0.55 | C5: 1 | D5: 1.35
A6: Operating margin delta (pp) | B6: -0.03 | C6: 0 | D6: 0.02
A7: WACC delta (pp) | B7: 0.01 | C7: 0 | D7: -0.01
A8: Terminal growth delta (pp) | B8: -0.005 | C8: 0 | D8: 0.005
A10: Scenario WACC | B10: ='DCF'!$B$22+B7 | C10: ='DCF'!$B$22+C7 | D10: ='DCF'!$B$22+D7
A11: Scenario Terminal Growth | B11: ='DCF'!$B$48+B8 | C11: ='DCF'!$B$48+C8 | D11: ='DCF'!$B$48+D8
A13: Year 1 FCF | B13: =((('DCF'!$B$28*(1+('DCF'!C26*B5)))*('DCF'!C30+B6))*(1-'DCF'!$B$15))+(('DCF'!$B$28*(1+('DCF'!C26*B5)))*'DCF'!C35)-(('DCF'!$B$28*(1+('DCF'!C26*B5)))*'DCF'!C37) | C13: =((('DCF'!$B$28*(1+('DCF'!C26*C5)))*('DCF'!C30+C6))*(1-'DCF'!$B$15))+(('DCF'!$B$28*(1+('DCF'!C26*C5)))*'DCF'!C35)-(('DCF'!$B$28*(1+('DCF'!C26*C5)))*'DCF'!C37) | D13: =((('DCF'!$B$28*(1+('DCF'!C26*D5)))*('DCF'!C30+D6))*(1-'DCF'!$B$15))+(('DCF'!$B$28*(1+('DCF'!C26*D5)))*'DCF'!C35)-(('DCF'!$B$28*(1+('DCF'!C26*D5)))*'DCF'!C37)
A14: Year 2 FCF | B14: =(((('DCF'!$B$28*(1+('DCF'!C26*$B$5)))*(1+('DCF'!D26*$B$5)))*('DCF'!D30+$B$6))*(1-'DCF'!$B$15))+((('DCF'!$B$28*(1+('DCF'!C26*$B$5)))*(1+('DCF'!D26*$B$5)))*'DCF'!D35)-((('DCF'!$B$28*(1+('DCF'!C26*$B$5)))*(1+('DCF'!D26*$B$5)))*'DCF'!D37) | C14: =(((('DCF'!$B$28*(1+'DCF'!C26))*(1+('DCF'!D26*$C$5)))*('DCF'!D30+$C$6))*(1-'DCF'!$B$15))+((('DCF'!$B$28*(1+'DCF'!C26))*(1+('DCF'!D26*$C$5)))*'DCF'!D35)-((('DCF'!$B$28*(1+'DCF'!C26))*(1+('DCF'!D26*$C$5)))*'DCF'!D37) | D14: =(((('DCF'!$B$28*(1+('DCF'!C26*$D$5)))*(1+('DCF'!D26*$D$5)))*('DCF'!D30+$D$6))*(1-'DCF'!$B$15))+((('DCF'!$B$28*(1+('DCF'!C26*$D$5)))*(1+('DCF'!D26*$D$5)))*'DCF'!D35)-((('DCF'!$B$28*(1+('DCF'!C26*$D$5)))*(1+('DCF'!D26*$D$5)))*'DCF'!D37)
A15: Year 3 FCF | B15: =((((('DCF'!$B$28*(1+('DCF'!C26*$B$5)))*(1+('DCF'!D26*$B$5)))*(1+('DCF'!E26*$B$5)))*('DCF'!E30+$B$6))*(1-'DCF'!$B$15))+(((('DCF'!$B$28*(1+('DCF'!C26*$B$5)))*(1+('DCF'!D26*$B$5)))*(1+('DCF'!E26*$B$5)))*'DCF'!E35)-(((('DCF'!$B$28*(1+('DCF'!C26*$B$5)))*(1+('DCF'!D26*$B$5)))*(1+('DCF'!E26*$B$5)))*'DCF'!E37) | C15: =((((('DCF'!$B$28*(1+'DCF'!C26))*(1+('DCF'!D26*$C$5)))*(1+('DCF'!E26*$C$5)))*('DCF'!E30+$C$6))*(1-'DCF'!$B$15))+(((('DCF'!$B$28*(1+'DCF'!C26))*(1+('DCF'!D26*$C$5)))*(1+('DCF'!E26*$C$5)))*'DCF'!E35)-(((('DCF'!$B$28*(1+'DCF'!C26))*(1+('DCF'!D26*$C$5)))*(1+('DCF'!E26*$C$5)))*'DCF'!E37) | D15: =((((('DCF'!$B$28*(1+('DCF'!C26*$D$5)))*(1+('DCF'!D26*$D$5)))*(1+('DCF'!E26*$D$5)))*('DCF'!E30+$D$6))*(1-'DCF'!$B$15))+(((('DCF'!$B$28*(1+('DCF'!C26*$D$5)))*(1+('DCF'!D26*$D$5)))*(1+('DCF'!E26*$D$5)))*'DCF'!E35)-(((('DCF'!$B$28*(1+('DCF'!C26*$D$5)))*(1+('DCF'!D26*$D$5)))*(1+('DCF'!E26*$D$5)))*'DCF'!E37)
A16: Year 4 FCF | B16: =(((((('DCF'!$B$28*(1+('DCF'!C26*$B$5)))*(1+('DCF'!D26*$B$5)))*(1+('DCF'!E26*$B$5)))*(1+('DCF'!F26*$B$5)))*('DCF'!F30+$B$6))*(1-'DCF'!$B$15))+((((('DCF'!$B$28*(1+('DCF'!C26*$B$5)))*(1+('DCF'!D26*$B$5)))*(1+('DCF'!E26*$B$5)))*(1+('DCF'!F26*$B$5)))*'DCF'!F35)-((((('DCF'!$B$28*(1+('DCF'!C26*$B$5)))*(1+('DCF'!D26*$B$5)))*(1+('DCF'!E26*$B$5)))*(1+('DCF'!F26*$B$5)))*'DCF'!F37) | C16: =(((((('DCF'!$B$28*(1+'DCF'!C26))*(1+('DCF'!D26*$C$5)))*(1+('DCF'!E26*$C$5)))*(1+('DCF'!F26*$C$5)))*('DCF'!F30+$C$6))*(1-'DCF'!$B$15))+((((('DCF'!$B$28*(1+'DCF'!C26))*(1+('DCF'!D26*$C$5)))*(1+('DCF'!E26*$C$5)))*(1+('DCF'!F26*$C$5)))*'DCF'!F35)-((((('DCF'!$B$28*(1+'DCF'!C26))*(1+('DCF'!D26*$C$5)))*(1+('DCF'!E26*$C$5)))*(1+('DCF'!F26*$C$5)))*'DCF'!F37) | D16: =(((((('DCF'!$B$28*(1+('DCF'!C26*$D$5)))*(1+('DCF'!D26*$D$5)))*(1+('DCF'!E26*$D$5)))*(1+('DCF'!F26*$D$5)))*('DCF'!F30+$D$6))*(1-'DCF'!$B$15))+((((('DCF'!$B$28*(1+('DCF'!C26*$D$5)))*(1+('DCF'!D26*$D$5)))*(1+('DCF'!E26*$D$5)))*(1+('DCF'!F26*$D$5)))*'DCF'!F35)-((((('DCF'!$B$28*(1+('DCF'!C26*$D$5)))*(1+('DCF'!D26*$D$5)))*(1+('DCF'!E26*$D$5)))*(1+('DCF'!F26*$D$5)))*'DCF'!F37)
A17: Year 5 FCF | B17: =((((((('DCF'!$B$28*(1+('DCF'!C26*$B$5)))*(1+('DCF'!D26*$B$5)))*(1+('DCF'!E26*$B$5)))*(1+('DCF'!F26*$B$5)))*(1+('DCF'!G26*$B$5)))*('DCF'!G30+$B$6))*(1-'DCF'!$B$15))+(((((('DCF'!$B$28*(1+('DCF'!C26*$B$5)))*(1+('DCF'!D26*$B$5)))*(1+('DCF'!E26*$B$5)))*(1+('DCF'!F26*$B$5)))*(1+('DCF'!G26*$B$5)))*'DCF'!G35)-(((((('DCF'!$B$28*(1+('DCF'!C26*$B$5)))*(1+('DCF'!D26*$B$5)))*(1+('DCF'!E26*$B$5)))*(1+('DCF'!F26*$B$5)))*(1+('DCF'!G26*$B$5)))*'DCF'!G37) | C17: =((((((('DCF'!$B$28*(1+'DCF'!C26))*(1+('DCF'!D26*$C$5)))*(1+('DCF'!E26*$C$5)))*(1+('DCF'!F26*$C$5)))*(1+('DCF'!G26*$C$5)))*('DCF'!G30+$C$6))*(1-'DCF'!$B$15))+(((((('DCF'!$B$28*(1+'DCF'!C26))*(1+('DCF'!D26*$C$5)))*(1+('DCF'!E26*$C$5)))*(1+('DCF'!F26*$C$5)))*(1+('DCF'!G26*$C$5)))*'DCF'!G35)-(((((('DCF'!$B$28*(1+'DCF'!C26))*(1+('DCF'!D26*$C$5)))*(1+('DCF'!E26*$C$5)))*(1+('DCF'!F26*$C$5)))*(1+('DCF'!G26*$C$5)))*'DCF'!G37) | D17: =((((((('DCF'!$B$28*(1+('DCF'!C26*$D$5)))*(1+('DCF'!D26*$D$5)))*(1+('DCF'!E26*$D$5)))*(1+('DCF'!F26*$D$5)))*(1+('DCF'!G26*$D$5)))*('DCF'!G30+$D$6))*(1-'DCF'!$B$15))+(((((('DCF'!$B$28*(1+('DCF'!C26*$D$5)))*(1+('DCF'!D26*$D$5)))*(1+('DCF'!E26*$D$5)))*(1+('DCF'!F26*$D$5)))*(1+('DCF'!G26*$D$5)))*'DCF'!G35)-(((((('DCF'!$B$28*(1+('DCF'!C26*$D$5)))*(1+('DCF'!D26*$D$5)))*(1+('DCF'!E26*$D$5)))*(1+('DCF'!F26*$D$5)))*(1+('DCF'!G26*$D$5)))*'DCF'!G37)
A19: Sum of PV of FCF (Yr 1-5) | B19: =B13/(1+B10)^1+B14/(1+B10)^2+B15/(1+B10)^3+B16/(1+B10)^4+B17/(1+B10)^5 | C19: =C13/(1+C10)^1+C14/(1+C10)^2+C15/(1+C10)^3+C16/(1+C10)^4+C17/(1+C10)^5 | D19: =D13/(1+D10)^1+D14/(1+D10)^2+D15/(1+D10)^3+D16/(1+D10)^4+D17/(1+D10)^5
A20: Terminal Value | B20: =B17*(1+B11)/(B10-B11) | C20: =C17*(1+C11)/(C10-C11) | D20: =D17*(1+D11)/(D10-D11)
A21: PV of Terminal Value | B21: =B20/(1+B10)^5 | C21: =C20/(1+C10)^5 | D21: =D20/(1+D10)^5
A22: Enterprise Value | B22: =B19+B21 | C22: =C19+C21 | D22: =D19+D21
A23: Equity Value | B23: =B22-'DCF'!$B$9 | C23: =C22-'DCF'!$B$9 | D23: =D22-'DCF'!$B$9
A24: Implied Share Price (model currency) | B24: =B23/'DCF'!$B$8 | C24: =C23/'DCF'!$B$8 | D24: =D23/'DCF'!$B$8
A25: Implied Share Price (p, quoted units) | B25: =B24*'DCF'!$B$6 | C25: =C24*'DCF'!$B$6 | D25: =D24*'DCF'!$B$6
A26: Upside / (Downside) vs. Current Price | B26: =B25/'DCF'!$B$5-1 | C26: =C25/'DCF'!$B$5-1 | D26: =D25/'DCF'!$B$5-1
A27: Current Share Price (reference) | B27: ='DCF'!$B$5 | C27: ='DCF'!$B$5 | D27: ='DCF'!$B$5

Sheet Sources
A1: Diploma PLC — Data Sources & Assumptions
A3: Input | B3: Source / Note
A4: Current Share Price | B4: 7,525p as of 22 Jul 2026 (stockanalysis.com / site pitch)
A5: Shares Outstanding | B5: 134.09m (stockanalysis.com, Aug 2026)
A6: Net Debt / Net Cash | B6: Net debt £383.2m (cash £81.7m, debt £464.9m) — stockanalysis.com
A7: Beta | B7: 1.04 (stockanalysis.com)
A8: Risk-Free Rate | B8: UK 10-year gilt yield, 4.99% (4 Aug 2026, tradingeconomics.com)
A9: Equity Risk Premium | B9: Standard mature-market equity risk premium assumption (~5%, Damodaran-style)
A10: Pre-Tax Cost of Debt | B10: Modeled: UK gilt yield + ~80bp investment-grade spread (assumption, not quoted)
A11: Tax Rate | B11: UK statutory corporate tax rate, 25%
A12: FY0 Revenue | B12: FY2025 revenue £1,524.5m (Diploma FY25 results, 18 Nov 2025)
A13: FY0 Operating Margin | B13: FY2025 operating margin 22.5% (£342.7m op. profit / £1,524.5m revenue)
A14: Revenue Growth Path (Yr 1-5) | B14: Y1 from Q1 FY26 reported growth (+17%); tapering toward a mid-single-digit long-run rate as the Peerless/PAR bolt-ons annualize
... A21: Compiled | B21: Web research conducted August 2026 for Bloombruh's stock-pitch Research Toolkits. This is a dated snapshot, not a live feed — verify current prices/fundamentals before relying on this for a real investment decision. See this pitch's own Research Toolkit page for further primary-source links.
