Workbook

Sheet READ ME
A1: Domino's Pizza Group — Valuation Workbook Template — How to Use
A4: ORDER OF WORK — workbook first, deck second. The deck's numbers must come FROM this file, never retyped.
A6: 1. Fill every yellow cell on the 'Inputs' tab. Each row says exactly where to pull the number.
A7: 2. Check the 'Scenarios' tab — the Bear/Base/Bull multipliers are editable modeling choices, not facts.
A8: 3. Read your Bear/Base/Bull values per share and the weighted target on the 'DCF' tab summary block.
A9: 4. SANITY CHECK before anything else: a LONG needs the target ABOVE today's price. If your weighted target
A10: is below the current price, the honest pitch is AVOID or SHORT (a short won OAF — see the Altria deck).
A11: 5. 'Reverse DCF' tab: Excel Goal Seek finds the growth the CURRENT price implies — that goes on the
A12: deck's Market Expectations slide.
A13: 6. 'Comps' tab: pull the listed peers (+optional extra). Median row computes itself.
A14: 7. Log every number on the 'Sources' tab with the date you pulled it. That becomes the deck's Appendix D.
A15: 8. The morning you present: re-pull the share price and check nothing material moved.
... A22: Colour code: YELLOW = you must fill this in. BLUE = formula, do not touch.

Sheet Inputs
A1: Inputs — fill every yellow cell (source noted on the right)
A3: Input | B3: Value | C3: Where to find it
A4: Share price (quote currency) | C4: stockanalysis.com or the exchange — LSE: DOM — pull fresh the day you build
A5: Shares outstanding (m) | C5: stockanalysis.com → Statistics
A6: Net debt (reporting currency, m) | C6: Latest annual/interim report (borrowings less cash)
A7: FY0 revenue (reporting currency, m) | C7: Latest annual report
A8: FY0 EBIT margin | C8: Latest annual report — operating profit / revenue
A9: Tax rate | C9: Annual report — effective tax rate
A10: D&A as % of revenue | C10: Cash-flow statement ÷ revenue
A11: Capex as % of revenue | C11: Cash-flow statement ÷ revenue
A12: Increase in NWC as % of revenue | C12: Cash-flow statement ÷ revenue
A13: Risk-free rate | C13: 10-year UK gilt yield — Bank of England
A14: Beta | C14: stockanalysis.com — do not guess it
A15: Equity risk premium | B15: 0.05 | C15: 5% is a standard assumption — editable
A16: Pre-tax cost of debt | C16: Interest expense ÷ gross debt, from annual report
A17: Terminal growth rate | C17: Long-run nominal GDP-ish: 2-3% is defensible
A18: Base revenue growth (Y1-5, pre-multiplier) | C18: Your forecast — anchor on recent reported growth + guidance
A19: Scenario weight — Bear | B19: 0.25 | C19: Editable modeling choice
A20: Scenario weight — Base | B20: 0.5 | C20: Editable modeling choice
A21: Scenario weight — Bull | B21: 0.25 | C21: Editable modeling choice
A22: Quote divisor (100 = pence/øre pricing, 1 = unit pricing) | B22: 100 | C22: GBX (pence) — see READ ME warnings

Sheet Scenarios
A1: Scenarios — editable modeling choices (you WILL be asked to defend these)
A3: Case | B3: Growth multiplier | C3: Margin delta (bps) | D3: WACC delta (bps) | E3: What the case says
A4: Bear | B4: 0.55 | C4: -100 | D4: 100 | E4: [EDIT: what has to go wrong — name the company-specific driver]
A5: Base | B5: 1 | C5: 0 | D5: 0 | E5: As modeled — recent momentum fades toward the fade rate
A6: Bull | B6: 1.35 | C6: 100 | D6: -100 | E6: [EDIT: what has to go right — name the company-specific driver]

Sheet DCF
A1: DCF — 5-year unlevered FCF, three scenarios (blue cells are formulas)
A3: WACC build
A4: Cost of equity (CAPM) | B4: =Inputs!B13+Inputs!B14*Inputs!B15
A5: After-tax cost of debt | B5: =Inputs!B16*(1-Inputs!B9)
A6: Market cap (reporting-ccy m) | B6: =Inputs!B4/Inputs!B22*Inputs!B5
A7: Weight of equity / debt | B7: =B6/(B6+Inputs!B6) | C7: =1-B7
A8: Base WACC | B8: =B7*B4+C7*B5
A9: Bear WACC / Bull WACC | B9: =B8+Scenarios!D4/10000 | C9: =B8+Scenarios!D6/10000
A12: Bear case | B12: =B9
B13: FY1 | C13: FY2 | D13: FY3 | E13: FY4 | F13: FY5
A14: Revenue | B14: =Inputs!B7*(1+(Inputs!B18*Scenarios!B4)) | C14: =B14*(1+(Inputs!B18*Scenarios!B4)) | D14: =C14*(1+(Inputs!B18*Scenarios!B4)) | E14: =D14*(1+(Inputs!B18*Scenarios!B4)) | F14: =E14*(1+(Inputs!B18*Scenarios!B4)) | G14: =F14*(1+(Inputs!B18*Scenarios!B4))
A15: EBIT margin | B15: =(Inputs!B8+Scenarios!C4/10000) | C15: =(Inputs!B8+Scenarios!C4/10000) | D15: =(Inputs!B8+Scenarios!C4/10000) | E15: =(Inputs!B8+Scenarios!C4/10000) | F15: =(Inputs!B8+Scenarios!C4/10000) | G15: =(Inputs!B8+Scenarios!C4/10000)
A16: EBIT | B16: =B14*B15 | C16: =C14*C15 | D16: =D14*D15 | E16: =E14*E15 | F16: =F14*F15 | G16: =G14*G15
A17: NOPAT | B17: =B16*(1-Inputs!B9) | C17: =C16*(1-Inputs!B9) | D17: =D16*(1-Inputs!B9) | E17: =E16*(1-Inputs!B9) | F17: =F16*(1-Inputs!B9) | G17: =G16*(1-Inputs!B9)
A18: Plus: D&A | B18: =B14*Inputs!B10 | C18: =C14*Inputs!B10 | D18: =D14*Inputs!B10 | E18: =E14*Inputs!B10 | F18: =F14*Inputs!B10 | G18: =G14*Inputs!B10
A19: Less: capex | B19: =B14*Inputs!B11 | C19: =C14*Inputs!B11 | D19: =D14*Inputs!B11 | E19: =E14*Inputs!B11 | F19: =F14*Inputs!B11 | G19: =G14*Inputs!B11
A20: Less: increase in NWC | B20: =B14*Inputs!B12 | C20: =C14*Inputs!B12 | D20: =D14*Inputs!B12 | E20: =E14*Inputs!B12 | F20: =F14*Inputs!B12 | G20: =G14*Inputs!B12
A21: Unlevered FCF | B21: =B17+B18-B19-B20 | C21: =C17+C18-C19-C20 | D21: =D17+D18-D19-D20 | E21: =E17+E18-E19-E20 | F21: =F17+F18-F19-F20 | G21: =G17+G18-G19-G20
A22: Discount factor | B22: =1/(1+$B$12)^1 | C22: =1/(1+$B$12)^2 | D22: =1/(1+$B$12)^3 | E22: =1/(1+$B$12)^4 | F22: =1/(1+$B$12)^5 | G22: =1/(1+$B$12)^6
A23: PV of FCF | B23: =B21*B22 | C23: =C21*C22 | D23: =D21*D22 | E23: =E21*E22 | F23: =F21*F22 | G23: =G21*G22
A24: Terminal value (Gordon, on FY5 FCF) | B24: =G21*(1+Inputs!B17)/($B$12-Inputs!B17)
A25: PV of terminal value | B25: =B24*G22
A26: Enterprise value | B26: =SUM(B23:G23)+B25
A27: Equity value (EV less net debt) | B27: =B26-Inputs!B6
A28: Value per share (quote currency) | B28: =B27/Inputs!B5*Inputs!B22
A31: Base case | B31: =B8
B32: FY1 | C32: FY2 | D32: FY3 | E32: FY4 | F32: FY5
A33: Revenue | B33: =Inputs!B7*(1+(Inputs!B18*Scenarios!B5)) | C33: =B33*(1+(Inputs!B18*Scenarios!B5)) | D33: =C33*(1+(Inputs!B18*Scenarios!B5)) | E33: =D33*(1+(Inputs!B18*Scenarios!B5)) | F33: =E33*(1+(Inputs!B18*Scenarios!B5)) | G33: =F33*(1+(Inputs!B18*Scenarios!B5))
A34: EBIT margin | B34: =(Inputs!B8+Scenarios!C5/10000) | C34: =(Inputs!B8+Scenarios!C5/10000) | D34: =(Inputs!B8+Scenarios!C5/10000) | E34: =(Inputs!B8+Scenarios!C5/10000) | F34: =(Inputs!B8+Scenarios!C5/10000) | G34: =(Inputs!B8+Scenarios!C5/10000)
A35: EBIT | B35: =B33*B34 | C35: =C33*C34 | D35: =D33*D34 | E35: =E33*E34 | F35: =F33*F34 | G35: =G33*G34
A36: NOPAT | B36: =B35*(1-Inputs!B9) | C36: =C35*(1-Inputs!B9) | D36: =D35*(1-Inputs!B9) | E36: =E35*(1-Inputs!B9) | F36: =F35*(1-Inputs!B9) | G36: =G35*(1-Inputs!B9)
A37: Plus: D&A | B37: =B33*Inputs!B10 | C37: =C33*Inputs!B10 | D37: =D33*Inputs!B10 | E37: =E33*Inputs!B10 | F37: =F33*Inputs!B10 | G37: =G33*Inputs!B10
A38: Less: capex | B38: =B33*Inputs!B11 | C38: =C33*Inputs!B11 | D38: =D33*Inputs!B11 | E38: =E33*Inputs!B11 | F38: =F33*Inputs!B11 | G38: =G33*Inputs!B11
A39: Less: increase in NWC | B39: =B33*Inputs!B12 | C39: =C33*Inputs!B12 | D39: =D33*Inputs!B12 | E39: =E33*Inputs!B12 | F39: =F33*Inputs!B12 | G39: =G33*Inputs!B12
A40: Unlevered FCF | B40: =B36+B37-B38-B39 | C40: =C36+C37-C38-C39 | D40: =D36+D37-D38-D39 | E40: =E36+E37-E38-E39 | F40: =F36+F37-F38-F39 | G40: =G36+G37-G38-G39
A41: Discount factor | B41: =1/(1+$B$31)^1 | C41: =1/(1+$B$31)^2 | D41: =1/(1+$B$31)^3 | E41: =1/(1+$B$31)^4 | F41: =1/(1+$B$31)^5 | G41: =1/(1+$B$31)^6
A42: PV of FCF | B42: =B40*B41 | C42: =C40*C41 | D42: =D40*D41 | E42: =E40*E41 | F42: =F40*F41 | G42: =G40*G41
A43: Terminal value (Gordon, on FY5 FCF) | B43: =G40*(1+Inputs!B17)/($B$31-Inputs!B17)
A44: PV of terminal value | B44: =B43*G41
A45: Enterprise value | B45: =SUM(B42:G42)+B44
...

Sheet Reverse DCF
A1: Reverse DCF — what the current price already implies
A4: Goal: find the revenue growth rate at which the Base-case DCF value EQUALS today's share price.
A5: That 'implied growth' goes on the deck's Market Expectations slide next to your own forecast.
A7: Steps (Excel):
A8: 1. Note the current price cell: DCF!B72 (pulled from Inputs).
A9: 2. Data → What-If Analysis → Goal Seek.
A10: 3. Set cell: DCF!C70 (Base-case value per share)
A11: 4. To value: the current share price (quote currency).
A12: 5. By changing cell: Inputs!B18 (Base revenue growth).
A13: Implied Base-case revenue growth (after Goal Seek) | B13: =Inputs!B18
A15: Now fill this slide table for the deck:
A16: Metric | B16: Historical | C16: Implied by price | D16: Your forecast | E16: Gap
A17: Revenue CAGR
A18: Operating margin
A19: EPS growth

Sheet Comps
A1: Trading Comps — pull every yellow cell from stockanalysis.com (same day for all)
A3: Company | B3: Ticker | C3: Mkt cap (m) | D3: EV (m) | E3: EBITDA (m) | F3: EV/EBITDA | G3: P/E | H3: Rev. growth | I3: EBIT margin
A4: Greggs | B4: LSE: GRG | F4: =IF(OR(D4="",E4=""),"",D4/E4)
A5: The Restaurant Group | B5: LSE: RTN | F5: =IF(OR(D5="",E5=""),"",D5/E5)
A6: [INSERT optional 3rd] | F6: =IF(OR(D6="",E6=""),"",D6/E6)
A7: [INSERT optional extra comp] | F7: =IF(OR(D7="",E7=""),"",D7/E7)
A8: Domino's Pizza Group | B8: LSE: DOM | F8: =IF(OR(D8="",E8=""),"",D8/E8)
A9: Median (peers only) | F9: =MEDIAN(F4:F7) | G9: =MEDIAN(G4:G7) | H9: =MEDIAN(H4:H7) | I9: =MEDIAN(I4:I7)
A11: If a judge asks why your target should trade above/below the median: answer with growth, margin, and ROIC differences. Have the sentence ready.

Sheet Sources
A1: Sources — every number, where from, when pulled (becomes deck Appendix D)
A3: Input | B3: Value | C3: Source | D3: Date pulled
A4: Share price
A5: Shares outstanding
A6: Net debt
A7: Beta
A8: Risk-free rate
A9: Equity risk premium
A10: Pre-tax cost of debt
A11: Tax rate
A12: FY0 revenue
A13: FY0 EBIT margin
A14: D&A % of revenue
A15: Capex % of revenue
... A21: Reverse-DCF implied growth
